Workbook

Sheet 1.표지
C2: 프로젝트명 | D2: 실사용데이터(RWD) 기반의 임상연구 지원 사업
C3: 산출물명 | D3: 업무규칙 및 프로파일링 구축 보고서

Sheet 2.작성가이드
B1: 구축 보고서
B4: □ 작성 가이드
B6: 산출물명 | C6: 산출물명 | D6: 항목분류 | F6: 설명
B7: 컬럼별 데이터 분포 진단 | C7: 항목-구분번호 | D7: 항목분류 | E7: id | F7: 품질진단 구분 번호
C8: 데이터셋 | D8: 테이블정보 | E8: 테이블명 | F8: 테이블명 혹은 파일명
C9: 항목 - 컬럼 | D9: 컬럼정보 | E9: 컬럼명 | F9: 해당 테이블의 컬럼명
E10: 데이터 수 (null을 제외한 데이터 수) | F10: 해당 컬럼에 저장된 NULL을 제외한 데이터의 수
C11: 속성분석 | D11: 기초집계값 | E11: 고유값 수 | F11: 해당 컬럼에 저장된 고유한 값의 수
E12: 최빈값 | F12: 가장 많은 수를 가지는 값
E13: 최빈값 빈도 | F13: 최빈값의 수
E14: 평균값 | F14: 해당 컬럼에 저장된 데이터의 평균 값 (숫자가 아닌 경우 빈값)
E15: 표준편차 | F15: 해당 컬럼에 저장된 데이터의 표준편차 값 (숫자가 아닌 경우 빈값)
E16: 최소값 | F16: 해당 컬럼에 저장된 데이터의 최소 값 (숫자가 아닌 경우 빈값)
E17: 0.25 | F17: 해당 컬럼에 저장된 데이터의 25%에 해당하는 값 (숫자가 아닌 경우 빈값)
E18: 0.5 | F18: 해당 컬럼에 저장된 데이터의 50%에 해당하는 값 (숫자가 아닌 경우 빈값)
E19: 0.75 | F19: 해당 컬럼에 저장된 데이터의 75%에 해당하는 값 (숫자가 아닌 경우 빈값)
E20: 최대값 | F20: 해당 컬럼에 저장된 데이터의 최대 값 (숫자가 아닌 경우 빈값)
E21: null데이터 수 | F21: 해당 컬럼에 있는 NULL 데이터 수
E22: null비율 | F22: 전체 데이터 대비 NULL값 백분율(NULL값 ROW수 / 전체 ROW 수)
B23: 메타데이터 진단 | C23: 항목-구분번호 | D23: 항목분류 | E23: id | F23: 품질진단 구분 번호
C24: 데이터셋 | D24: 테이블정보 | E24: 테이블명 | F24: 테이블명 혹은 파일명
C25: 항목 - 컬럼 | D25: 컬럼정보 | E25: 컬럼명 | F25: 해당 테이블의 컬럼명
C26: 정의내역 | D26: 규칙 정의 | E26: 품질지표 | F26: 데이터 품질관리 지표(정확성)
E27: 품질상세지표 | F27: 데이터 품질관리 상세지표(메타 데이터 정확성)
E28: 진단규칙내용 | F28: 품질진단을 수행 할 내용
C29: 결과내역 | D29: 결과 | E29: 항목 데이터 수 | F29: 총 건수 결과
E30: 전체 데이터 수 | F30: 진단 규칙 조건에 해당하는 건수 결과
E31: 항목 환자 수 | F31: 총 환자수 결과
E32: 전체 환자 수 | F32: 진단 규칙 조건에 해당하는 환자수 결과
E33: 검사 시행 환자 비율 | F33: 진단 규칙에 해당하는 환자수 비율
B34: 업무규칙 결과 | C34: 항목-구분번호 | D34: 항목분류 | E34: id | F34: 품질진단 구분 번호
C35: 데이터셋 | D35: 테이블정보 | E35: 테이블명 | F35: 테이블명 혹은 파일명
C36: 항목 - 컬럼 | D36: 컬럼정보 | E36: 컬럼명 | F36: 해당 테이블의 컬럼명
C37: 정의내역 | D37: 규칙 정의 | E37: 품질지표 | F37: 데이터 품질관리 지표 (유효성, 정확성, 완전성, 일관성)
E38: 품질상세지표 | F38: 데이터 품질관리 상세지표 (참조무결성, 중복일관성, 범위유효성, 논리관계정확성, 단독완전성 등)
E39: 진단규칙내용 | F39: 품질진단을 수행 할 내용
C40: 결과내역 | D40: 결과 | E40: 오류 건수 | F40: 총 오류 건수 결과
E41: 총 건수 | F41: 총 건수 결과
E42: 오류율 | F42: 오류율 결과 (오류 건수 / 총 건수)

Sheet 3.컬럼별_데이터_분포 진단결과
A1: id | B1: 테이블명 | C1: 컬럼명 | D1: 데이터 수 (null을 제외한 데이터 수) | E1: 고유값 수 | F1: 최빈값 | G1: 최빈값 빈도 | H1: 평균값 | I1: 표준편차 | J1: 최소값 | K1: 0.25 | L1: 0.5 | M1: 0.75 | N1: 최대값 | O1: null데이터 수 | P1: null비율
A2: field_0001 | B2: care_site | C2: care_site_id | D2: 1003 | E2: 1003 | F2: 1 | G2: 1 | H2: 502 | I2: 289.68546 | J2: 1 | K2: 251.5 | L2: 502 | M2: 752.5 | N2: 1003 | O2: 0 | P2: 0
A3: field_0001 | B3: care_site | C3: care_site_name | D3: 1003 | E3: 997 | F3: 요역동학검사실 | G3: 2 | O3: 0 | P3: 0
A4: field_0001 | B4: care_site | C4: place_of_service_concept_id | D4: 1003 | E4: 1 | F4: 0 | G4: 1003 | H4: 0 | I4: 0 | J4: 0 | K4: 0 | L4: 0 | M4: 0 | N4: 0 | O4: 0 | P4: 0
A5: field_0001 | B5: care_site | C5: location_id | D5: 1003 | E5: 1 | F5: 417 | G5: 1003 | H5: 417 | I5: 0 | J5: 417 | K5: 417 | L5: 417 | M5: 417 | N5: 417 | O5: 0 | P5: 0
A6: field_0001 | B6: care_site | C6: care_site_source_value | D6: 1002 | E6: 1002 | F6: Z00011 | G6: 1 | O6: 1 | P6: 0.00099700897
A7: field_0001 | B7: care_site | C7: place_of_service_source_value | D7: 0 | E7: 0 | G7: 0 | O7: 1003 | P7: 1
A8: field_0002 | B8: provider | C8: provider_id | D8: 15270 | E8: 15270 | F8: 1 | G8: 1 | H8: 7635.5 | I8: 4408.2136 | J8: 1 | K8: 3818.25 | L8: 7635.5 | M8: 11452.75 | N8: 15270 | O8: 0 | P8: 0
A9: field_0002 | B9: provider | C9: provider_name | D9: 15259 | E9: 13008 | F9: N | G9: 79 | O9: 11 | P9: 0.00072036673
A10: field_0002 | B10: provider | C10: npi | D10: 0 | E10: 0 | G10: 0 | O10: 15270 | P10: 1
A11: field_0002 | B11: provider | C11: dea | D11: 0 | E11: 0 | G11: 0 | O11: 15270 | P11: 1
A12: field_0002 | B12: provider | C12: specialty_concept_id | D12: 15270 | E12: 3 | F12: 0 | G12: 9007 | H12: 13362.31 | I12: 16024.875 | J12: 0 | K12: 0 | L12: 0 | M12: 32577 | N12: 32581 | O12: 0 | P12: 0
A13: field_0002 | B13: provider | C13: specialty_concept_id_name | D13: 6263 | E13: 2 | F13: Nurse | G13: 3181 | O13: 9007 | P13: 0.58984938
A14: field_0002 | B14: provider | C14: care_site_id | D14: 15254 | E14: 329 | F14: 413 | G14: 1334 | H14: 397.11708 | I14: 210.79536 | J14: 21 | K14: 230 | L14: 407 | M14: 536 | N14: 1001 | O14: 16 | P14: 0.0010478062
A15: field_0002 | B15: provider | C15: care_site_name | D15: 15254 | E15: 327 | F15: 임상시험센터 | G15: 1334 | O15: 16 | P15: 0.0010478062
A16: field_0002 | B16: provider | C16: year_of_birth | D16: 0 | E16: 0 | G16: 0 | O16: 15270 | P16: 1
A17: field_0002 | B17: provider | C17: gender_concept_id | D17: 15270 | E17: 1 | F17: 0 | G17: 15270 | H17: 0 | I17: 0 | J17: 0 | K17: 0 | L17: 0 | M17: 0 | N17: 0 | O17: 0 | P17: 0
A18: field_0002 | B18: provider | C18: provider_source_value | D18: 15269 | E18: 15269 | F18: 21740 | G18: 1 | O18: 1 | P18: 6.5487885e-05
A19: field_0002 | B19: provider | C19: specialty_source_value | D19: 11411 | E19: 106 | F19: 500 | G19: 2478 | O19: 3859 | P19: 0.25271775
A20: field_0002 | B20: provider | C20: specialty_source_value_name | D20: 15270 | E20: 104 | F20: 구분없음 | G20: 3862 | O20: 0 | P20: 0
A21: field_0002 | B21: provider | C21: specialty_source_concept_id | D21: 15270 | E21: 1 | F21: 0 | G21: 15270 | H21: 0 | I21: 0 | J21: 0 | K21: 0 | L21: 0 | M21: 0 | N21: 0 | O21: 0 | P21: 0
A22: field_0002 | B22: provider | C22: gender_source_value | D22: 0 | E22: 0 | G22: 0 | O22: 15270 | P22: 1
A23: field_0002 | B23: provider | C23: gender_source_concept_id | D23: 15270 | E23: 1 | F23: 0 | G23: 15270 | H23: 0 | I23: 0 | J23: 0 | K23: 0 | L23: 0 | M23: 0 | N23: 0 | O23: 0 | P23: 0
A24: field_0003 | B24: person | C24: person_id | D24: 6147 | E24: 6147 | F24: 1 | G24: 1 | H24: 3074 | I24: 1774.6304 | J24: 1 | K24: 1537.5 | L24: 3074 | M24: 4610.5 | N24: 6147 | O24: 0 | P24: 0
A25: field_0003 | B25: person | C25: gender_concept_id | D25: 6147 | E25: 2 | F25: 8532 | G25: 3223 | H25: 8520.108 | I25: 12.486219 | J25: 8507 | K25: 8507 | L25: 8532 | M25: 8532 | N25: 8532 | O25: 0 | P25: 0
A26: field_0003 | B26: person | C26: year_of_birth | D26: 6147 | E26: 111 | F26: 1942 | G26: 177 | H26: 1962.7589 | I26: 27.756386 | J26: 1903 | K26: 1941 | L26: 1954 | M26: 1980 | N26: 2023 | O26: 0 | P26: 0
A27: field_0003 | B27: person | C27: month_of_birth | D27: 6147 | E27: 12 | F27: 1 | G27: 636 | H27: 6.2571986 | I27: 3.5638924 | J27: 1 | K27: 3 | L27: 6 | M27: 9 | N27: 12 | O27: 0 | P27: 0
A28: field_0003 | B28: person | C28: day_of_birth | D28: 6147 | E28: 31 | F28: 20 | G28: 328 | H28: 15.119733 | I28: 8.6509667 | J28: 1 | K28: 8 | L28: 15 | M28: 22 | N28: 31 | O28: 0 | P28: 0
A29: field_0003 | B29: person | C29: birth_datetime | D29: 6147 | E29: 5403 | F29: 12804 | G29: 6 | H29: 23097.511 | J29: 1295 | K29: 15259 | L29: 20011 | M29: 29228 | N29: 45234 | O29: 0 | P29: 0
A30: field_0003 | B30: person | C30: death_datetime | D30: 391 | E30: 344 | F30: 44641 | G30: 3 | H30: 44172.747 | J30: 37227 | K30: 44220 | L30: 44707 | M30: 45000 | N30: 45354 | O30: 5756 | P30: 0.93639174
A31: field_0003 | B31: person | C31: race_concept_id | D31: 6147 | E31: 2 | F31: 38003585 | G31: 6083 | H31: 37607997 | I31: 3856984 | J31: 8552 | K31: 38003585 | L31: 38003585 | M31: 38003585 | N31: 38003585 | O31: 0 | P31: 0
A32: field_0003 | B32: person | C32: ethnicity_concept_id | D32: 0 | E32: 0 | G32: 0 | O32: 6147 | P32: 1
A33: field_0003 | B33: person | C33: location_id | D33: 6147 | E33: 141 | F33: 417 | G33: 771 | H33: 383.93574 | I33: 108.0933 | J33: 0 | K33: 409 | L33: 416 | M33: 418 | N33: 451 | O33: 0 | P33: 0
A34: field_0003 | B34: person | C34: provider_id | D34: 6147 | E34: 1 | F34: 0 | G34: 6147 | H34: 0 | I34: 0 | J34: 0 | K34: 0 | L34: 0 | M34: 0 | N34: 0 | O34: 0 | P34: 0
A35: field_0003 | B35: person | C35: care_site_id | D35: 6147 | E35: 1 | F35: 0 | G35: 6147 | H35: 0 | I35: 0 | J35: 0 | K35: 0 | L35: 0 | M35: 0 | N35: 0 | O35: 0 | P35: 0
A36: field_0003 | B36: person | C36: person_source_value | D36: 6147 | E36: 6147 | F36: 111719 | G36: 1 | H36: 1441039.2 | I36: 542431.21 | J36: 111719 | K36: 1019793 | L36: 1439461 | M36: 1940806.5 | N36: 3064617 | O36: 0 | P36: 0
A37: field_0003 | B37: person | C37: 환자명 | D37: 6147 | E37: 5450 | F37: 김정순 | G37: 13 | O37: 0 | P37: 0
A38: field_0003 | B38: person | C38: gender_source_value | D38: 6147 | E38: 2 | F38: F | G38: 3223 | O38: 0 | P38: 0
A39: field_0003 | B39: person | C39: gender_source_concept_id | D39: 6147 | E39: 2 | F39: 8532 | G39: 3223 | H39: 8520.108 | I39: 12.486219 | J39: 8507 | K39: 8507 | L39: 8532 | M39: 8532 | N39: 8532 | O39: 0 | P39: 0
A40: field_0003 | B40: person | C40: race_source_value | D40: 6147 | E40: 2 | F40: 1 | G40: 5250 | H40: 1.1459248 | I40: 0.35305957 | J40: 1 | K40: 1 | L40: 1 | M40: 1 | N40: 2 | O40: 0 | P40: 0
...

Sheet 4.메타_데이터_진단결과
A1: id | B1: 테이블명 | C1: 컬럼명 | D1: 품질지표 | E1: 품질상세지표 | F1: 진단규칙내용 | G1: 항목 데이터 수 | H1: 전체 데이터 수 | I1: 항목 환자 수 | J1: 전체 환자 수 | K1: 검사 시행 환자 비율
A2: META_0001 | B2: measurement | C2: measurement_source_value | D2: 정확성 | E2: 메타 데이터 정확성 | F2: wbc_count에 대한 데이터가 있어야 함 | G2: 144888 | H2: 13568812 | I2: 5974 | J2: 6133 | K2: 0.97407468
A3: META_0002 | B3: measurement | C3: measurement_source_value | D3: 정확성 | E3: 메타 데이터 정확성 | F3: hb에 대한 데이터가 있어야 함 | G3: 144888 | H3: 13568812 | I3: 5974 | J3: 6133 | K3: 0.97407468
A4: META_0003 | B4: measurement | C4: measurement_source_value | D4: 정확성 | E4: 메타 데이터 정확성 | F4: hematocrit에 대한 데이터가 있어야 함 | G4: 144888 | H4: 13568812 | I4: 5974 | J4: 6133 | K4: 0.97407468
A5: META_0004 | B5: measurement | C5: measurement_source_value | D5: 정확성 | E5: 메타 데이터 정확성 | F5: platelet_count에 대한 데이터가 있어야 함 | G5: 144888 | H5: 13568812 | I5: 5974 | J5: 6133 | K5: 0.97407468
A6: META_0005 | B6: measurement | C6: measurement_source_value | D6: 정확성 | E6: 메타 데이터 정확성 | F6: lymphocyte_count에 대한 데이터가 있어야 함 | G6: 107510 | H6: 13568812 | I6: 5549 | J6: 6133 | K6: 0.90477743
A7: META_0006 | B7: measurement | C7: measurement_source_value | D7: 정확성 | E7: 메타 데이터 정확성 | F7: monocyte_count에 대한 데이터가 있어야 함 | G7: 107510 | H7: 13568812 | I7: 5549 | J7: 6133 | K7: 0.90477743
A8: META_0007 | B8: measurement | C8: measurement_source_value | D8: 정확성 | E8: 메타 데이터 정확성 | F8: neurophil_count에 대한 데이터가 있어야 함 | G8: 107510 | H8: 13568812 | I8: 5549 | J8: 6133 | K8: 0.90477743
A9: META_0008 | B9: measurement | C9: measurement_source_value | D9: 정확성 | E9: 메타 데이터 정확성 | F9: sodium에 대한 데이터가 있어야 함 | G9: 122868 | H9: 13568812 | I9: 6013 | J9: 6133 | K9: 0.98043372
A10: META_0009 | B10: measurement | C10: measurement_source_value | D10: 정확성 | E10: 메타 데이터 정확성 | F10: potassium에 대한 데이터가 있어야 함 | G10: 123010 | H10: 13568812 | I10: 6013 | J10: 6133 | K10: 0.98043372
A11: META_0010 | B11: measurement | C11: measurement_source_value | D11: 정확성 | E11: 메타 데이터 정확성 | F11: ast에 대한 데이터가 있어야 함 | G11: 109477 | H11: 13568812 | I11: 5951 | J11: 6133 | K11: 0.97032447
A12: META_0011 | B12: measurement | C12: measurement_source_value | D12: 정확성 | E12: 메타 데이터 정확성 | F12: alt에 대한 데이터가 있어야 함 | G12: 109434 | H12: 13568812 | I12: 5952 | J12: 6133 | K12: 0.97048753
A13: META_0012 | B13: measurement | C13: measurement_source_value | D13: 정확성 | E13: 메타 데이터 정확성 | F13: total_bilirubin에 대한 데이터가 있어야 함 | G13: 98541 | H13: 13568812 | I13: 5922 | J13: 6133 | K13: 0.96559596
... A33: META_0032 | B33: measurement | C33: measurement_source_value | D33: 정확성 | E33: 메타 데이터 정확성 | F33: weight에 대한 데이터가 있어야 함 | G33: 656187 | H33: 13568812 | I33: 4129 | J33: 6133 | K33: 0.67324311

Sheet 5.업무규칙_결과
A1: id | B1: 테이블명 | C1: 컬럼명 | D1: 품질지표 | E1: 품질상세지표 | F1: 진단규칙내용 | G1: 오류 건수 | H1: 총 건수 | I1: 오류율
A2: DQ_0001 | B2: person | C2: person_source_value | D2: 완전성 | E2: 데이터 값 완전성 | F2: person_source_value는 NULL이나 공백 데이터가 없어야 한다 | G2: 0 | H2: 6147 | I2: 0
A3: DQ_0002 | B3: person | C3: person_source_value | D3: 유일성 | E3: 데이터 값 유일성 | F3: person_source_value는 중복값 없이 유일해야 한다 | G3: 0 | H3: 6147 | I3: 0
A4: DQ_0003 | B4: person | C4: year_of_birth | D4: 유효성 | E4: 범위 유효성 | F4: 내일 이전 날짜로 채워져야 한다. | G4: 0 | H4: 6147 | I4: 0
A5: DQ_0004 | B5: person | C5: month_of_birth | D5: 유효성 | E5: 범위 유효성 | F5: 1에서 12사이의 값으로 채워져야 한다. | G5: 0 | H5: 6147 | I5: 0
A6: DQ_0005 | B6: person | C6: day_of_birth | D6: 유효성 | E6: 범위 유효성 | F6: 1에서 31 사이의 값으로 채워져야 한다. | G6: 0 | H6: 6147 | I6: 0
A7: DQ_0006 | B7: person | C7: gender_source_value | D7: 완전성 | E7: 데이터 값 완전성 | F7: gender_source_value는 null값이 아니어야한다. | G7: 0 | H7: 6147 | I7: 0
A8: DQ_0007 | B8: person | C8: death_datetime | D8: 유효성 | E8: 관계 유효성 | F8: 사망일이 환자 출생년도 이전이 될 수 없음 | G8: 0 | H8: 6147 | I8: 0
A9: DQ_0008 | B9: visit_occurrence | C9: visit_occurrence_id | D9: 완전성 | E9: 데이터 값 완전성 | F9: visit_occurrence_id컬럼에 NULL이나 공백 데이터가 존재할 수 없음 | G9: 0 | H9: 456446 | I9: 0
A10: DQ_0009 | B10: visit_occurrence | C10: visit_occurrence_id | D10: 유일성 | E10: 데이터 값 유일성 | F10: visit_occurrence_id는 중복값 없이 유일해야함 | G10: 0 | H10: 456446 | I10: 0
A11: DQ_0010 | B11: visit_occurrence | C11: visit_start_date | D11: 유효성 | E11: 관계 유효성 | F11: visit_occurrence테이블의 visit_start_date 컬럼은 visit_end_date 보다 작거나 같아야 한다. | G11: 0 | H11: 456446 | I11: 0
A12: DQ_0011 | B12: visit_occurrence | C12: visit_start_date | D12: 완전성 | E12: 데이터 값 완전성 | F12: visit_start_date 데이터는 NULL데이터를 가질 수 없음 | G12: 0 | H12: 456446 | I12: 0
A13: DQ_0012 | B13: visit_occurrence | C13: visit_start_datetime | D13: 완전성 | E13: 데이터 값 완전성 | F13: visit_start_datetime 데이터는 NULL데이터를 가질 수 없음 | G13: 0 | H13: 456446 | I13: 0
... A51: DQ_0050 | B51: observation_period | C51: person_id | D51: 일관성 | E51: 참조 무결 일관성 | F51: observation_period의 person_id는 person에 등록된 값이어야 함 | G51: 0 | H51: 6147 | I51: 0

Sheet 6.업무규칙_결과요약
C2: CDM | D2: 개수 | E2: 비율 | F2: 총건수 | G2: 오류건수 | H2: 오류율
C3: 완전성 | D3: =COUNTIF('5.업무규칙_결과'!D2:D51, "완전성") -> 25 | E3: =D3/D12 -> 0.5 | F3: =SUMIF('5.업무규칙_결과'!D2:D51, "완전성", '5.업무규칙_결과'!H2:H51) -> 89731703 | G3: =SUMIF('5.업무규칙_결과'!D2:D51, "완전성", '5.업무규칙_결과'!G2:G51) -> 65 | H3: =G3/F3 -> 7.2438166e-07
C4: 데이터 값 완전성 | D4: =COUNTIF('5.업무규칙_결과'!E2:E51, "데이터 값 완전성") -> 25 | E4: =D3/D4 -> 1 | F4: =SUMIF('5.업무규칙_결과'!E2:E51, "데이터 값 완전성", '5.업무규칙_결과'!H2:H51) -> 89731703 | G4: =SUMIF('5.업무규칙_결과'!E2:E51, "데이터 값 완전성", '5.업무규칙_결과'!G2:G51) -> 65 | H4: =G4/F4 -> 7.2438166e-07
C5: 유일성 | D5: =COUNTIF('5.업무규칙_결과'!D2:D51, "유일성") -> 7 | E5: =D5/D12 -> 0.14 | F5: =SUMIF('5.업무규칙_결과'!D2:D51, "유일성", '5.업무규칙_결과'!H2:H51) -> 22437536 | G5: =SUMIF('5.업무규칙_결과'!D2:D51, "유일성", '5.업무규칙_결과'!I2:I51) -> 0 | H5: =G5/F5 -> 0
C6: 데이터 값 유일성 | D6: =COUNTIF('5.업무규칙_결과'!E2:E51, "데이터 값 유일성") -> 7 | E6: =D5/D6 -> 1 | F6: =SUMIF('5.업무규칙_결과'!E2:E51, "데이터 값 유일성", '5.업무규칙_결과'!H2:H51) -> 22437536 | G6: =SUMIF('5.업무규칙_결과'!E2:E51, "데이터 값 유일성", '5.업무규칙_결과'!G2:G51) -> 0 | H6: =G6/F6 -> 0
C7: 유효성 | D7: =COUNTIF('5.업무규칙_결과'!D2:D51, "유효성") -> 8 | E7: =D7/D12 -> 0.16 | F7: =SUMIF('5.업무규칙_결과'!D2:D51, "유효성", '5.업무규칙_결과'!H2:H51) -> 4997110 | G7: =SUMIF('5.업무규칙_결과'!D2:D51, "유효성", '5.업무규칙_결과'!G2:G51) -> 48 | H7: =G7/F7 -> 9.605552e-06
C8: 관계 유효성 | D8: =COUNTIF('5.업무규칙_결과'!E2:E51, "관계 유효성") -> 5 | E8: =D8/D7 -> 0.625 | F8: =SUMIF('5.업무규칙_결과'!E2:E51, "관계 유효성", '5.업무규칙_결과'!H2:H51) -> 4978669 | G8: =SUMIF('5.업무규칙_결과'!E2:E51, "관계 유효성", '5.업무규칙_결과'!G2:G51) -> 48 | H8: =G8/F8 -> 9.641131e-06
C9: 범위 유효성 | D9: =COUNTIF('5.업무규칙_결과'!E2:E51, "범위 유효성") -> 3 | E9: =D9/D7 -> 0.375 | F9: =SUMIF('5.업무규칙_결과'!E2:E51, "범위 유효성", '5.업무규칙_결과'!H2:H51) -> 18441 | G9: =SUMIF('5.업무규칙_결과'!E2:E51, "범위 유효성", '5.업무규칙_결과'!G2:G51) -> 0 | H9: =G9/F9 -> 0
C10: 일관성 | D10: =COUNTIF('5.업무규칙_결과'!D2:D51, "일관성") -> 10 | E10: =D10/D12 -> 0.2 | F10: =SUMIF('5.업무규칙_결과'!D2:D51, "일관성", '5.업무규칙_결과'!H2:H51) -> 44400264 | G10: =SUMIF('5.업무규칙_결과'!D2:D51, "일관성", '5.업무규칙_결과'!G2:G51) -> 2174235 | H10: =G10/F10 -> 0.048968966
C11: 참조 무결 일관성 | D11: =COUNTIF('5.업무규칙_결과'!E2:E51, "참조 무결 일관성") -> 10 | E11: =D11/D10 -> 1 | F11: =SUMIF('5.업무규칙_결과'!E2:E51, "참조 무결 일관성", '5.업무규칙_결과'!H2:H51) -> 44400264 | G11: =SUMIF('5.업무규칙_결과'!E2:E51, "참조 무결 일관성", '5.업무규칙_결과'!G2:G51) -> 2174235 | H11: =G11/F11 -> 0.048968966
C12: 총합계 | D12: =SUM(D3,D5,D7,D10) -> 50 | E12: =SUM(E3,E5,E7,E10) -> 1 | F12: =SUM(F3,F5,F7,F10) -> 161566613 | G12: =SUM(G3,G5,G7,G10) -> 2174348 | H12: =G12/F12 -> 0.013457904
